2024-12-09 13:49:05,545 INFO    MainThread:59054 [wandb_setup.py:_flush():79] Current SDK version is 0.18.7
2024-12-09 13:49:05,545 INFO    MainThread:59054 [wandb_setup.py:_flush():79] Configure stats pid to 59054
2024-12-09 13:49:05,545 INFO    MainThread:59054 [wandb_setup.py:_flush():79] Loading settings from /Users/seunadekunle/.config/wandb/settings
2024-12-09 13:49:05,545 INFO    MainThread:59054 [wandb_setup.py:_flush():79] Loading settings from /Users/seunadekunle/school/567/style_classifier/wandb/settings
2024-12-09 13:49:05,545 INFO    MainThread:59054 [wandb_setup.py:_flush():79] Loading settings from environment variables: {}
2024-12-09 13:49:05,545 INFO    MainThread:59054 [wandb_setup.py:_flush():79] Applying setup settings: {'mode': None, '_disable_service': None}
2024-12-09 13:49:05,545 INFO    MainThread:59054 [wandb_setup.py:_flush():79] Inferring run settings from compute environment: {'program_relpath': 'src/training/train_darn.py', 'program_abspath': '/Users/seunadekunle/school/567/style_classifier/src/training/train_darn.py', 'program': '/Users/seunadekunle/school/567/style_classifier/src/training/train_darn.py'}
2024-12-09 13:49:05,545 INFO    MainThread:59054 [wandb_setup.py:_flush():79] Applying login settings: {}
2024-12-09 13:49:05,545 INFO    MainThread:59054 [wandb_init.py:_log_setup():533] Logging user logs to /Users/seunadekunle/school/567/style_classifier/wandb/run-20241209_134905-dme19blj/logs/debug.log
2024-12-09 13:49:05,545 INFO    MainThread:59054 [wandb_init.py:_log_setup():534] Logging internal logs to /Users/seunadekunle/school/567/style_classifier/wandb/run-20241209_134905-dme19blj/logs/debug-internal.log
2024-12-09 13:49:05,545 INFO    MainThread:59054 [wandb_init.py:init():619] calling init triggers
2024-12-09 13:49:05,545 INFO    MainThread:59054 [wandb_init.py:init():626] wandb.init called with sweep_config: {}
config: {'data_root': 'data_deepfashion', 'batch_size': 32, 'num_workers': 4, 'backbone': 'resnet34', 'embedding_dim': 512, 'dropout': 0.5, 'epochs': 50, 'lr': 0.0001, 'weight_decay': 0.0001, 'margin': 0.3, 'attribute_weight': 1.0, 'ranking_weight': 1.0, 'label_smoothing': 0.1, 'scheduler': 'cosine', 'warmup_epochs': 5, 'min_lr': 1e-06, 'log_dir': 'logs', 'checkpoint_dir': 'checkpoints', 'experiment_name': 'darn_resnet34_baseline', 'wandb': True, 'visualize_every': 5, 'test_mode': True, 'device': 'cpu'}
2024-12-09 13:49:05,545 INFO    MainThread:59054 [wandb_init.py:init():669] starting backend
2024-12-09 13:49:05,545 INFO    MainThread:59054 [wandb_init.py:init():673] sending inform_init request
2024-12-09 13:49:05,546 INFO    MainThread:59054 [backend.py:_multiprocessing_setup():104] multiprocessing start_methods=spawn,fork,forkserver, using: spawn
2024-12-09 13:49:05,546 INFO    MainThread:59054 [wandb_init.py:init():686] backend started and connected
2024-12-09 13:49:05,548 INFO    MainThread:59054 [wandb_init.py:init():781] updated telemetry
2024-12-09 13:49:05,576 INFO    MainThread:59054 [wandb_init.py:init():814] communicating run to backend with 90.0 second timeout
2024-12-09 13:49:06,662 INFO    Thread-1  :59054 [retry.py:__call__():172] Retry attempt failed:
Traceback (most recent call last):
  File "/Users/seunadekunle/miniconda3/envs/style_classifier/lib/python3.9/site-packages/urllib3/connection.py", line 199, in _new_conn
    sock = connection.create_connection(
  File "/Users/seunadekunle/miniconda3/envs/style_classifier/lib/python3.9/site-packages/urllib3/util/connection.py", line 60, in create_connection
    for res in socket.getaddrinfo(host, port, family, socket.SOCK_STREAM):
  File "/Users/seunadekunle/miniconda3/envs/style_classifier/lib/python3.9/socket.py", line 966, in getaddrinfo
    for res in _socket.getaddrinfo(host, port, family, type, proto, flags):
socket.gaierror: [Errno 8] nodename nor servname provided, or not known

The above exception was the direct cause of the following exception:

Traceback (most recent call last):
  File "/Users/seunadekunle/miniconda3/envs/style_classifier/lib/python3.9/site-packages/urllib3/connectionpool.py", line 789, in urlopen
    response = self._make_request(
  File "/Users/seunadekunle/miniconda3/envs/style_classifier/lib/python3.9/site-packages/urllib3/connectionpool.py", line 490, in _make_request
    raise new_e
  File "/Users/seunadekunle/miniconda3/envs/style_classifier/lib/python3.9/site-packages/urllib3/connectionpool.py", line 466, in _make_request
    self._validate_conn(conn)
  File "/Users/seunadekunle/miniconda3/envs/style_classifier/lib/python3.9/site-packages/urllib3/connectionpool.py", line 1095, in _validate_conn
    conn.connect()
  File "/Users/seunadekunle/miniconda3/envs/style_classifier/lib/python3.9/site-packages/urllib3/connection.py", line 693, in connect
    self.sock = sock = self._new_conn()
  File "/Users/seunadekunle/miniconda3/envs/style_classifier/lib/python3.9/site-packages/urllib3/connection.py", line 206, in _new_conn
    raise NameResolutionError(self.host, self, e) from e
urllib3.exceptions.NameResolutionError: <urllib3.connection.HTTPSConnection object at 0x319ab4d00>: Failed to resolve 'api.wandb.ai' ([Errno 8] nodename nor servname provided, or not known)

The above exception was the direct cause of the following exception:

Traceback (most recent call last):
  File "/Users/seunadekunle/miniconda3/envs/style_classifier/lib/python3.9/site-packages/requests/adapters.py", line 667, in send
    resp = conn.urlopen(
  File "/Users/seunadekunle/miniconda3/envs/style_classifier/lib/python3.9/site-packages/urllib3/connectionpool.py", line 843, in urlopen
    retries = retries.increment(
  File "/Users/seunadekunle/miniconda3/envs/style_classifier/lib/python3.9/site-packages/urllib3/util/retry.py", line 519, in increment
    raise MaxRetryError(_pool, url, reason) from reason  # type: ignore[arg-type]
urllib3.exceptions.MaxRetryError: HTTPSConnectionPool(host='api.wandb.ai', port=443): Max retries exceeded with url: /graphql (Caused by NameResolutionError("<urllib3.connection.HTTPSConnection object at 0x319ab4d00>: Failed to resolve 'api.wandb.ai' ([Errno 8] nodename nor servname provided, or not known)"))

During handling of the above exception, another exception occurred:

Traceback (most recent call last):
  File "/Users/seunadekunle/miniconda3/envs/style_classifier/lib/python3.9/site-packages/wandb/sdk/lib/retry.py", line 131, in __call__
    result = self._call_fn(*args, **kwargs)
  File "/Users/seunadekunle/miniconda3/envs/style_classifier/lib/python3.9/site-packages/wandb/sdk/internal/internal_api.py", line 400, in execute
    return self.client.execute(*args, **kwargs)  # type: ignore
  File "/Users/seunadekunle/miniconda3/envs/style_classifier/lib/python3.9/site-packages/wandb/vendor/gql-0.2.0/wandb_gql/client.py", line 52, in execute
    result = self._get_result(document, *args, **kwargs)
  File "/Users/seunadekunle/miniconda3/envs/style_classifier/lib/python3.9/site-packages/wandb/vendor/gql-0.2.0/wandb_gql/client.py", line 60, in _get_result
    return self.transport.execute(document, *args, **kwargs)
  File "/Users/seunadekunle/miniconda3/envs/style_classifier/lib/python3.9/site-packages/wandb/sdk/lib/gql_request.py", line 58, in execute
    request = self.session.post(self.url, **post_args)
  File "/Users/seunadekunle/miniconda3/envs/style_classifier/lib/python3.9/site-packages/requests/sessions.py", line 637, in post
    return self.request("POST", url, data=data, json=json, **kwargs)
  File "/Users/seunadekunle/miniconda3/envs/style_classifier/lib/python3.9/site-packages/requests/sessions.py", line 589, in request
    resp = self.send(prep, **send_kwargs)
  File "/Users/seunadekunle/miniconda3/envs/style_classifier/lib/python3.9/site-packages/requests/sessions.py", line 703, in send
    r = adapter.send(request, **kwargs)
  File "/Users/seunadekunle/miniconda3/envs/style_classifier/lib/python3.9/site-packages/requests/adapters.py", line 700, in send
    raise ConnectionError(e, request=request)
requests.exceptions.ConnectionError: HTTPSConnectionPool(host='api.wandb.ai', port=443): Max retries exceeded with url: /graphql (Caused by NameResolutionError("<urllib3.connection.HTTPSConnection object at 0x319ab4d00>: Failed to resolve 'api.wandb.ai' ([Errno 8] nodename nor servname provided, or not known)"))
2024-12-09 13:50:35,976 ERROR   MainThread:59054 [wandb_init.py:init():841] encountered error: Run initialization has timed out after 90.0 sec. Please try increasing the timeout with the `init_timeout` setting: `wandb.init(settings=wandb.Settings(init_timeout=120))`.
2024-12-09 13:50:35,976 ERROR   MainThread:59054 [wandb_init.py:init():1266] error in wandb.init()
Traceback (most recent call last):
  File "/Users/seunadekunle/miniconda3/envs/style_classifier/lib/python3.9/site-packages/wandb/sdk/wandb_init.py", line 1256, in init
    return wi.init()
  File "/Users/seunadekunle/miniconda3/envs/style_classifier/lib/python3.9/site-packages/wandb/sdk/wandb_init.py", line 847, in init
    raise error
wandb.errors.errors.CommError: Run initialization has timed out after 90.0 sec. Please try increasing the timeout with the `init_timeout` setting: `wandb.init(settings=wandb.Settings(init_timeout=120))`.
2024-12-09 13:50:35,986 WARNING MsgRouterThr:59054 [router.py:message_loop():75] message_loop has been closed
